Workbook

Sheet Datos
A1: Año | B1: Industria | C1: Estado | D1: Establecimientos | E1: Empleados | F1: Salario anual promedio
A2: 2024 | B2: Energía | C2: Alabama | D2: 4029 | E2: 24510 | F2: 53206
A3: 2024 | B3: Energía | C3: Arizona | D3: 13917 | E3: 148837 | F3: 71561
A4: 2024 | B4: Energía | C4: Arkansas | D4: 2283 | E4: 11124 | F4: 57486
A5: 2024 | B5: Energía | C5: California | D5: 21888 | E5: 245234 | F5: 55653
A6: 2024 | B6: Energía | C6: Colorado | D6: 35993 | E6: 430516 | F6: 56745
A7: 2024 | B7: Energía | C7: Connecticut | D7: 14308 | E7: 146700 | F7: 60316
A8: 2024 | B8: Energía | C8: Delaware | D8: 208425 | E8: 2667839 | F8: 91070
A9: 2024 | B9: Energía | C9: Florida | D9: 52525 | E9: 423946 | F9: 81401
A10: 2024 | B10: Energía | C10: Georgia | D10: 23279 | E10: 221029 | F10: 87958
A11: 2024 | B11: Energía | C11: Idaho | D11: 8956 | E11: 63405 | F11: 80066
A12: 2024 | B12: Energía | C12: Illinois | D12: 161890 | E12: 1365136 | F12: 60914
A13: 2024 | B13: Energía | C13: Indiana | D13: 54714 | E13: 687321 | F13: 66989
... A1919: 2021 | B1919: Tecnología | C1919: Wyoming | D1919: 1656 | E1919: 7231 | F1919: 35035

Sheet Instrucciones

Sheet Tablas
A1: FILTRO INDUSTRIA | E1: SALARIO MEDIO POR INDUSTRIA | I1: EMPLEADOS POR INDUSTRIA | N1: TENDECIAS SALARIOS Y EMPLEADOS | T1: Comparacion por estado | AA1: Estado | AB1: Poblacion
A2: Indice | B2: INDUSTRIA | C2: SELECCIÓN | E2: INDUSTRIA | F2: Salario promedio annual | G2: Seleccion | I2: INDUSTRIA | J2: EMPLEADOS | N2: AÑO | O2: SALARIO PROMEDIO | P2: EMPLEADOS | T2: Estado | U2: Empleados | V2: Poblacion | W2: Empleados por 100 capita | X2: Salario promedio | Y2: =C29 -> Empleados por 100 capita | AA2: #VALUE! | AB2: {=_FV(AA2,"Población")} -> 5157699
A3: 10 | B3: {=_xlfn._xlws.SORT(_xlfn.UNIQUE(Datos!B2:B1919))} -> Comercio electrónico | C3: ='Dashboard (format control)'!B7 -> Finanzas | E3: Comercio electrónico | F3: =AVERAGEIFS(Datos!$F:$F,Datos!$B:$B,Tablas!E3,Datos!$A:$A,Tablas!$C$18) -> 62625.292 | G3: =IF(E3=$C$3,F3,0) -> 0 | I3: Comercio electrónico | J3: =SUMIFS(Datos!$E:$E,Datos!$A:$A,Tablas!$C$18,Datos!$B:$B,Tablas!I3) -> 12378010 | M3: 1 | N3: 2021 | O3: =AVERAGEIFS(Datos!$F:$F,Datos!$A:$A,Tablas!N3,Datos!$B:$B,Tablas!$C$3) -> 77330.083 | P3: =SUMIFS(Datos!$E:$E,Datos!$A:$A,Tablas!N3,Datos!$B:$B,Tablas!$C$3) -> 8021586 | T3: Alabama | U3: =SUMIFS(Datos!E:E,Datos!A:A,Tablas!C$18,Datos!B:B,Tablas!C$3,Datos!C:C,Tablas!T3) -> 94756 | V3: 5157699 | W3: =U3/V3*1000 -> 18.371758 | X3: =AVERAGEIFS(Datos!$F:$F,Datos!$A:$A,Tablas!$C$18,Datos!$B:$B,Tablas!$C$3,Datos!$C:$C,Tablas!T3) -> 66324 | Y3: =IF($Y$2=$X$2,-X3,-W3) -> -18.371758 | AA3: #VALUE! | AB3: {=_FV(AA3,"Población")} -> 7582384
A4: 9 | B4: Comunicación | E4: Comunicación | F4: =AVERAGEIFS(Datos!$F:$F,Datos!$B:$B,Tablas!E4,Datos!$A:$A,Tablas!$C$18) -> 75580.708 | G4: =IF(E4=$C$3,F4,0) -> 0 | I4: Comunicación | J4: =SUMIFS(Datos!$E:$E,Datos!$A:$A,Tablas!$C$18,Datos!$B:$B,Tablas!I4) -> 2761056 | M4: 2 | N4: 2022 | O4: =AVERAGEIFS(Datos!$F:$F,Datos!$A:$A,Tablas!N4,Datos!$B:$B,Tablas!$C$3) -> 80167.854 | P4: =SUMIFS(Datos!$E:$E,Datos!$A:$A,Tablas!N4,Datos!$B:$B,Tablas!$C$3) -> 8120224 | T4: Arizona | U4: =SUMIFS(Datos!E:E,Datos!A:A,Tablas!C$18,Datos!B:B,Tablas!C$3,Datos!C:C,Tablas!T4) -> 206540 | V4: 7582384 | W4: =U4/V4*1000 -> 27.239454 | X4: =AVERAGEIFS(Datos!$F:$F,Datos!$A:$A,Tablas!$C$18,Datos!$B:$B,Tablas!$C$3,Datos!$C:$C,Tablas!T4) -> 68059 | Y4: =IF($Y$2=$X$2,-X4,-W4) -> -27.239454 | AA4: #VALUE! | AB4: {=_FV(AA4,"Población")} -> 3088354
A5: 8 | B5: Educación | E5: Educación | F5: =AVERAGEIFS(Datos!$F:$F,Datos!$B:$B,Tablas!E5,Datos!$A:$A,Tablas!$C$18) -> 20737.417 | G5: =IF(E5=$C$3,F5,0) -> 0 | I5: Educación | J5: =SUMIFS(Datos!$E:$E,Datos!$A:$A,Tablas!$C$18,Datos!$B:$B,Tablas!I5) -> 15665534 | M5: 3 | N5: 2023 | O5: =AVERAGEIFS(Datos!$F:$F,Datos!$A:$A,Tablas!N5,Datos!$B:$B,Tablas!$C$3) -> 82837.375 | P5: =SUMIFS(Datos!$E:$E,Datos!$A:$A,Tablas!N5,Datos!$B:$B,Tablas!$C$3) -> 8251469 | T5: Arkansas | U5: =SUMIFS(Datos!E:E,Datos!A:A,Tablas!C$18,Datos!B:B,Tablas!C$3,Datos!C:C,Tablas!T5) -> 49596 | V5: 3088354 | W5: =U5/V5*1000 -> 16.05904 | X5: =AVERAGEIFS(Datos!$F:$F,Datos!$A:$A,Tablas!$C$18,Datos!$B:$B,Tablas!$C$3,Datos!$C:$C,Tablas!T5) -> 55939 | Y5: =IF($Y$2=$X$2,-X5,-W5) -> -16.05904 | AA5: #VALUE! | AB5: {=_FV(AA5,"Población")} -> 39431263
A6: 7 | B6: Energía | E6: Energía | F6: =AVERAGEIFS(Datos!$F:$F,Datos!$B:$B,Tablas!E6,Datos!$A:$A,Tablas!$C$18) -> 51626.702 | G6: =IF(E6=$C$3,F6,0) -> 0 | I6: Energía | J6: =SUMIFS(Datos!$E:$E,Datos!$A:$A,Tablas!$C$18,Datos!$B:$B,Tablas!I6) -> 1864222 | M6: 4 | N6: 2024 | O6: =AVERAGEIFS(Datos!$F:$F,Datos!$A:$A,Tablas!N6,Datos!$B:$B,Tablas!$C$3) -> 90040.667 | P6: =SUMIFS(Datos!$E:$E,Datos!$A:$A,Tablas!N6,Datos!$B:$B,Tablas!$C$3) -> 8142043 | T6: California | U6: =SUMIFS(Datos!E:E,Datos!A:A,Tablas!C$18,Datos!B:B,Tablas!C$3,Datos!C:C,Tablas!T6) -> 827494 | V6: 39431263 | W6: =U6/V6*1000 -> 20.985734 | X6: =AVERAGEIFS(Datos!$F:$F,Datos!$A:$A,Tablas!$C$18,Datos!$B:$B,Tablas!$C$3,Datos!$C:$C,Tablas!T6) -> 104466 | Y6: =IF($Y$2=$X$2,-X6,-W6) -> -20.985734 | AA6: #VALUE! | AB6: {=_FV(AA6,"Población")} -> 5957493
A7: 6 | B7: Finanzas | E7: Finanzas | F7: =AVERAGEIFS(Datos!$F:$F,Datos!$B:$B,Tablas!E7,Datos!$A:$A,Tablas!$C$18) -> 77330.083 | G7: =IF(E7=$C$3,F7,0) -> 77330.083 | I7: Finanzas | J7: =SUMIFS(Datos!$E:$E,Datos!$A:$A,Tablas!$C$18,Datos!$B:$B,Tablas!I7) -> 8021586 | T7: Colorado | U7: =SUMIFS(Datos!E:E,Datos!A:A,Tablas!C$18,Datos!B:B,Tablas!C$3,Datos!C:C,Tablas!T7) -> 161870 | V7: 5957493 | W7: =U7/V7*1000 -> 27.170825 | X7: =AVERAGEIFS(Datos!$F:$F,Datos!$A:$A,Tablas!$C$18,Datos!$B:$B,Tablas!$C$3,Datos!$C:$C,Tablas!T7) -> 81536 | Y7: =IF($Y$2=$X$2,-X7,-W7) -> -27.170825 | AA7: #VALUE! | AB7: {=_FV(AA7,"Población")} -> 3675069
A8: 5 | B8: Logística | E8: Logística | F8: =AVERAGEIFS(Datos!$F:$F,Datos!$B:$B,Tablas!E8,Datos!$A:$A,Tablas!$C$18) -> 57353.83 | G8: =IF(E8=$C$3,F8,0) -> 0 | I8: Logística | J8: =SUMIFS(Datos!$E:$E,Datos!$A:$A,Tablas!$C$18,Datos!$B:$B,Tablas!I8) -> 6834462 | T8: Connecticut | U8: =SUMIFS(Datos!E:E,Datos!A:A,Tablas!C$18,Datos!B:B,Tablas!C$3,Datos!C:C,Tablas!T8) -> 126051 | V8: 3675069 | W8: =U8/V8*1000 -> 34.298948 | X8: =AVERAGEIFS(Datos!$F:$F,Datos!$A:$A,Tablas!$C$18,Datos!$B:$B,Tablas!$C$3,Datos!$C:$C,Tablas!T8) -> 152598 | Y8: =IF($Y$2=$X$2,-X8,-W8) -> -34.298948 | AA8: #VALUE! | AB8: {=_FV(AA8,"Población")} -> 1051917
A9: 4 | B9: Negocios | E9: Negocios | F9: =AVERAGEIFS(Datos!$F:$F,Datos!$B:$B,Tablas!E9,Datos!$A:$A,Tablas!$C$18) -> 64714.438 | G9: =IF(E9=$C$3,F9,0) -> 0 | I9: Negocios | J9: =SUMIFS(Datos!$E:$E,Datos!$A:$A,Tablas!$C$18,Datos!$B:$B,Tablas!I9) -> 20063464 | T9: Delaware | U9: =SUMIFS(Datos!E:E,Datos!A:A,Tablas!C$18,Datos!B:B,Tablas!C$3,Datos!C:C,Tablas!T9) -> 47894 | V9: 1051917 | W9: =U9/V9*1000 -> 45.530208 | X9: =AVERAGEIFS(Datos!$F:$F,Datos!$A:$A,Tablas!$C$18,Datos!$B:$B,Tablas!$C$3,Datos!$C:$C,Tablas!T9) -> 92267 | Y9: =IF($Y$2=$X$2,-X9,-W9) -> -45.530208 | AA9: #VALUE! | AB9: {=_FV(AA9,"Población")} -> 23372215
A10: 3 | B10: Salud | E10: Salud | F10: =AVERAGEIFS(Datos!$F:$F,Datos!$B:$B,Tablas!E10,Datos!$A:$A,Tablas!$C$18) -> 47654.729 | G10: =IF(E10=$C$3,F10,0) -> 0 | I10: Salud | J10: =SUMIFS(Datos!$E:$E,Datos!$A:$A,Tablas!$C$18,Datos!$B:$B,Tablas!I10) -> 21899196 | T10: Florida | U10: =SUMIFS(Datos!E:E,Datos!A:A,Tablas!C$18,Datos!B:B,Tablas!C$3,Datos!C:C,Tablas!T10) -> 556510 | V10: 23372215 | W10: =U10/V10*1000 -> 23.810751 | X10: =AVERAGEIFS(Datos!$F:$F,Datos!$A:$A,Tablas!$C$18,Datos!$B:$B,Tablas!$C$3,Datos!$C:$C,Tablas!T10) -> 72708 | Y10: =IF($Y$2=$X$2,-X10,-W10) -> -23.810751 | AA10: #VALUE! | AB10: {=_FV(AA10,"Población")} -> 11180878
A11: 2 | B11: Tecnología | E11: Tecnología | F11: =AVERAGEIFS(Datos!$F:$F,Datos!$B:$B,Tablas!E11,Datos!$A:$A,Tablas!$C$18) -> 34629.271 | G11: =IF(E11=$C$3,F11,0) -> 0 | I11: Tecnología | J11: =SUMIFS(Datos!$E:$E,Datos!$A:$A,Tablas!$C$18,Datos!$B:$B,Tablas!I11) -> 4326750 | T11: Georgia | U11: =SUMIFS(Datos!E:E,Datos!A:A,Tablas!C$18,Datos!B:B,Tablas!C$3,Datos!C:C,Tablas!T11) -> 233995 | V11: 11180878 | W11: =U11/V11*1000 -> 20.928142 | X11: =AVERAGEIFS(Datos!$F:$F,Datos!$A:$A,Tablas!$C$18,Datos!$B:$B,Tablas!$C$3,Datos!$C:$C,Tablas!T11) -> 81197 | Y11: =IF($Y$2=$X$2,-X11,-W11) -> -20.928142 | AA11: #VALUE! | AB11: {=_FV(AA11,"Población")} -> 2001619
A12: 1 | B12: Transporte | E12: Transporte | F12: =AVERAGEIFS(Datos!$F:$F,Datos!$B:$B,Tablas!E12,Datos!$A:$A,Tablas!$C$18) -> 43391.396 | G12: =IF(E12=$C$3,F12,0) -> 0 | I12: Transporte | J12: =SUMIFS(Datos!$E:$E,Datos!$A:$A,Tablas!$C$18,Datos!$B:$B,Tablas!I12) -> 27033069 | T12: Idaho | U12: =SUMIFS(Datos!E:E,Datos!A:A,Tablas!C$18,Datos!B:B,Tablas!C$3,Datos!C:C,Tablas!T12) -> 31064 | V12: 2001619 | W12: =U12/V12*1000 -> 15.519437 | X12: =AVERAGEIFS(Datos!$F:$F,Datos!$A:$A,Tablas!$C$18,Datos!$B:$B,Tablas!$C$3,Datos!$C:$C,Tablas!T12) -> 53820 | Y12: =IF($Y$2=$X$2,-X12,-W12) -> -15.519437 | AA12: #VALUE! | AB12: {=_FV(AA12,"Población")} -> 12710158
T13: Illinois | U13: =SUMIFS(Datos!E:E,Datos!A:A,Tablas!C$18,Datos!B:B,Tablas!C$3,Datos!C:C,Tablas!T13) -> 370517 | V13: 12710158 | W13: =U13/V13*1000 -> 29.151251 | X13: =AVERAGEIFS(Datos!$F:$F,Datos!$A:$A,Tablas!$C$18,Datos!$B:$B,Tablas!$C$3,Datos!$C:$C,Tablas!T13) -> 104689 | Y13: =IF($Y$2=$X$2,-X13,-W13) -> -29.151251 | AA13: #VALUE! | AB13: {=_FV(AA13,"Población")} -> 6924275
T14: Indiana | U14: =SUMIFS(Datos!E:E,Datos!A:A,Tablas!C$18,Datos!B:B,Tablas!C$3,Datos!C:C,Tablas!T14) -> 131758 | V14: 6924275 | W14: =U14/V14*1000 -> 19.028418 | X14: =AVERAGEIFS(Datos!$F:$F,Datos!$A:$A,Tablas!$C$18,Datos!$B:$B,Tablas!$C$3,Datos!$C:$C,Tablas!T14) -> 62518 | Y14: =IF($Y$2=$X$2,-X14,-W14) -> -19.028418 | AA14: #VALUE! | AB14: {=_FV(AA14,"Población")} -> 3241488
T15: Iowa | U15: =SUMIFS(Datos!E:E,Datos!A:A,Tablas!C$18,Datos!B:B,Tablas!C$3,Datos!C:C,Tablas!T15) -> 108983 | V15: 3241488 | W15: =U15/V15*1000 -> 33.621288 | X15: =AVERAGEIFS(Datos!$F:$F,Datos!$A:$A,Tablas!$C$18,Datos!$B:$B,Tablas!$C$3,Datos!$C:$C,Tablas!T15) -> 71597 | Y15: =IF($Y$2=$X$2,-X15,-W15) -> -33.621288 | AA15: #VALUE! | AB15: {=_FV(AA15,"Población")} -> 2970606
T16: Kansas | U16: =SUMIFS(Datos!E:E,Datos!A:A,Tablas!C$18,Datos!B:B,Tablas!C$3,Datos!C:C,Tablas!T16) -> 74321 | V16: 2970606 | W16: =U16/V16*1000 -> 25.018801 | X16: =AVERAGEIFS(Datos!$F:$F,Datos!$A:$A,Tablas!$C$18,Datos!$B:$B,Tablas!$C$3,Datos!$C:$C,Tablas!T16) -> 65845 | Y16: =IF($Y$2=$X$2,-X16,-W16) -> -25.018801 | AA16: #VALUE! | AB16: {=_FV(AA16,"Población")} -> 4588372
B17: FILTRO FECHA | I17: EMPLEADOS POR INDUSTRIA (LIMPIO) | T17: Kentucky | U17: =SUMIFS(Datos!E:E,Datos!A:A,Tablas!C$18,Datos!B:B,Tablas!C$3,Datos!C:C,Tablas!T17) -> 93126 | V17: 4588372 | W17: =U17/V17*1000 -> 20.296088 | X17: =AVERAGEIFS(Datos!$F:$F,Datos!$A:$A,Tablas!$C$18,Datos!$B:$B,Tablas!$C$3,Datos!$C:$C,Tablas!T17) -> 64967 | Y17: =IF($Y$2=$X$2,-X17,-W17) -> -20.296088 | AA17: #VALUE! | AB17: {=_FV(AA17,"Población")} -> 4597740
B18: AÑO ACTUAL: | C18: ='Dashboard (format control)'!D7 -> 2021 | I18: INDUSTRIA | J18: EMPLEADOS | T18: Louisiana | U18: =SUMIFS(Datos!E:E,Datos!A:A,Tablas!C$18,Datos!B:B,Tablas!C$3,Datos!C:C,Tablas!T18) -> 85771 | V18: 4597740 | W18: =U18/V18*1000 -> 18.655035 | X18: =AVERAGEIFS(Datos!$F:$F,Datos!$A:$A,Tablas!$C$18,Datos!$B:$B,Tablas!$C$3,Datos!$C:$C,Tablas!T18) -> 59758 | Y18: =IF($Y$2=$X$2,-X18,-W18) -> -18.655035 | AA18: #VALUE! | AB18: {=_FV(AA18,"Población")} -> 1405012
I19: =C3 -> Finanzas | J19: =_xlfn.XLOOKUP(I19, I3:I12, J3:J12) -> 8021586 | T19: Maine | U19: =SUMIFS(Datos!E:E,Datos!A:A,Tablas!C$18,Datos!B:B,Tablas!C$3,Datos!C:C,Tablas!T19) -> 29417 | V19: 1405012 | W19: =U19/V19*1000 -> 20.937188 | X19: =AVERAGEIFS(Datos!$F:$F,Datos!$A:$A,Tablas!$C$18,Datos!$B:$B,Tablas!$C$3,Datos!$C:$C,Tablas!T19) -> 65934 | Y19: =IF($Y$2=$X$2,-X19,-W19) -> -20.937188 | AA19: #VALUE! | AB19: {=_FV(AA19,"Población")} -> 6263220
I20: Otros | J20: =SUM(J3:K12)-J19 -> 112825763 | T20: Maryland | U20: =SUMIFS(Datos!E:E,Datos!A:A,Tablas!C$18,Datos!B:B,Tablas!C$3,Datos!C:C,Tablas!T20) -> 140287 | V20: 6263220 | W20: =U20/V20*1000 -> 22.398543 | X20: =AVERAGEIFS(Datos!$F:$F,Datos!$A:$A,Tablas!$C$18,Datos!$B:$B,Tablas!$C$3,Datos!$C:$C,Tablas!T20) -> 90791 | Y20: =IF($Y$2=$X$2,-X20,-W20) -> -22.398543 | AA20: #VALUE! | AB20: {=_FV(AA20,"Población")} -> 7136171
I21: PORCENTAJE | J21: =J19/SUM(J3:K12) -> 0.06637784 | T21: Massachusetts | U21: =SUMIFS(Datos!E:E,Datos!A:A,Tablas!C$18,Datos!B:B,Tablas!C$3,Datos!C:C,Tablas!T21) -> 216567 | V21: 7136171 | W21: =U21/V21*1000 -> 30.347787 | X21: =AVERAGEIFS(Datos!$F:$F,Datos!$A:$A,Tablas!$C$18,Datos!$B:$B,Tablas!$C$3,Datos!$C:$C,Tablas!T21) -> 136040 | Y21: =IF($Y$2=$X$2,-X21,-W21) -> -30.347787 | AA21: #VALUE! | AB21: {=_FV(AA21,"Población")} -> 10140459
T22: Michigan | U22: =SUMIFS(Datos!E:E,Datos!A:A,Tablas!C$18,Datos!B:B,Tablas!C$3,Datos!C:C,Tablas!T22) -> 202358 | V22: 10140459 | W22: =U22/V22*1000 -> 19.955507 | X22: =AVERAGEIFS(Datos!$F:$F,Datos!$A:$A,Tablas!$C$18,Datos!$B:$B,Tablas!$C$3,Datos!$C:$C,Tablas!T22) -> 69275 | Y22: =IF($Y$2=$X$2,-X22,-W22) -> -19.955507 | AA22: #VALUE! | AB22: {=_FV(AA22,"Población")} -> 5793151
T23: Minnesota | U23: =SUMIFS(Datos!E:E,Datos!A:A,Tablas!C$18,Datos!B:B,Tablas!C$3,Datos!C:C,Tablas!T23) -> 175945 | V23: 5793151 | W23: =U23/V23*1000 -> 30.371209 | X23: =AVERAGEIFS(Datos!$F:$F,Datos!$A:$A,Tablas!$C$18,Datos!$B:$B,Tablas!$C$3,Datos!$C:$C,Tablas!T23) -> 91036 | Y23: =IF($Y$2=$X$2,-X23,-W23) -> -30.371209 | AA23: #VALUE! | AB23: {=_FV(AA23,"Población")} -> 2943045
T24: Mississippi | U24: =SUMIFS(Datos!E:E,Datos!A:A,Tablas!C$18,Datos!B:B,Tablas!C$3,Datos!C:C,Tablas!T24) -> 42981 | V24: 2943045 | W24: =U24/V24*1000 -> 14.604262 | X24: =AVERAGEIFS(Datos!$F:$F,Datos!$A:$A,Tablas!$C$18,Datos!$B:$B,Tablas!$C$3,Datos!$C:$C,Tablas!T24) -> 51222 | Y24: =IF($Y$2=$X$2,-X24,-W24) -> -14.604262 | AA24: #VALUE! | AB24: {=_FV(AA24,"Población")} -> 6245466
T25: Missouri | U25: =SUMIFS(Datos!E:E,Datos!A:A,Tablas!C$18,Datos!B:B,Tablas!C$3,Datos!C:C,Tablas!T25) -> 163353 | V25: 6245466 | W25: =U25/V25*1000 -> 26.155454 | X25: =AVERAGEIFS(Datos!$F:$F,Datos!$A:$A,Tablas!$C$18,Datos!$B:$B,Tablas!$C$3,Datos!$C:$C,Tablas!T25) -> 68974 | Y25: =IF($Y$2=$X$2,-X25,-W25) -> -26.155454 | AA25: #VALUE! | AB25: {=_FV(AA25,"Población")} -> 1137233
T26: Montana | U26: =SUMIFS(Datos!E:E,Datos!A:A,Tablas!C$18,Datos!B:B,Tablas!C$3,Datos!C:C,Tablas!T26) -> 20935 | V26: 1137233 | W26: =U26/V26*1000 -> 18.408717 | X26: =AVERAGEIFS(Datos!$F:$F,Datos!$A:$A,Tablas!$C$18,Datos!$B:$B,Tablas!$C$3,Datos!$C:$C,Tablas!T26) -> 56708 | Y26: =IF($Y$2=$X$2,-X26,-W26) -> -18.408717 | AA26: #VALUE! | AB26: {=_FV(AA26,"Población")} -> 2005465
T27: Nebraska | U27: =SUMIFS(Datos!E:E,Datos!A:A,Tablas!C$18,Datos!B:B,Tablas!C$3,Datos!C:C,Tablas!T27) -> 66237 | V27: 2005465 | W27: =U27/V27*1000 -> 33.02825 | X27: =AVERAGEIFS(Datos!$F:$F,Datos!$A:$A,Tablas!$C$18,Datos!$B:$B,Tablas!$C$3,Datos!$C:$C,Tablas!T27) -> 63484 | Y27: =IF($Y$2=$X$2,-X27,-W27) -> -33.02825 | AA27: #VALUE! | AB27: {=_FV(AA27,"Población")} -> 3267467
B28: FILTRO MAPA | T28: Nevada | U28: =SUMIFS(Datos!E:E,Datos!A:A,Tablas!C$18,Datos!B:B,Tablas!C$3,Datos!C:C,Tablas!T28) -> 61375 | V28: 3267467 | W28: =U28/V28*1000 -> 18.783663 | X28: =AVERAGEIFS(Datos!$F:$F,Datos!$A:$A,Tablas!$C$18,Datos!$B:$B,Tablas!$C$3,Datos!$C:$C,Tablas!T28) -> 63979 | Y28: =IF($Y$2=$X$2,-X28,-W28) -> -18.783663 | AA28: #VALUE! | AB28: {=_FV(AA28,"Población")} -> 1409032
B29: METRICA | C29: =IF('Dashboard (format control)'!A1=1,X2,W2) -> Empleados por 100 capita | T29: New Hampshire | U29: =SUMIFS(Datos!E:E,Datos!A:A,Tablas!C$18,Datos!B:B,Tablas!C$3,Datos!C:C,Tablas!T29) -> 33894 | V29: 1409032 | W29: =U29/V29*1000 -> 24.054812 | X29: =AVERAGEIFS(Datos!$F:$F,Datos!$A:$A,Tablas!$C$18,Datos!$B:$B,Tablas!$C$3,Datos!$C:$C,Tablas!T29) -> 91139 | Y29: =IF($Y$2=$X$2,-X29,-W29) -> -24.054812 | AA29: #VALUE! | AB29: {=_FV(AA29,"Población")} -> 9288994
T30: New Jersey | U30: =SUMIFS(Datos!E:E,Datos!A:A,Tablas!C$18,Datos!B:B,Tablas!C$3,Datos!C:C,Tablas!T30) -> 241026 | V30: 9288994 | W30: =U30/V30*1000 -> 25.947482 | X30: =AVERAGEIFS(Datos!$F:$F,Datos!$A:$A,Tablas!$C$18,Datos!$B:$B,Tablas!$C$3,Datos!$C:$C,Tablas!T30) -> 111862 | Y30: =IF($Y$2=$X$2,-X30,-W30) -> -25.947482 | AA30: #VALUE! | AB30: {=_FV(AA30,"Población")} -> 2130256
T31: New Mexico | U31: =SUMIFS(Datos!E:E,Datos!A:A,Tablas!C$18,Datos!B:B,Tablas!C$3,Datos!C:C,Tablas!T31) -> 32604 | V31: 2130256 | W31: =U31/V31*1000 -> 15.305203 | X31: =AVERAGEIFS(Datos!$F:$F,Datos!$A:$A,Tablas!$C$18,Datos!$B:$B,Tablas!$C$3,Datos!$C:$C,Tablas!T31) -> 53932 | Y31: =IF($Y$2=$X$2,-X31,-W31) -> -15.305203 | AA31: #VALUE! | AB31: {=_FV(AA31,"Población")} -> 20201249
T32: New York | U32: =SUMIFS(Datos!E:E,Datos!A:A,Tablas!C$18,Datos!B:B,Tablas!C$3,Datos!C:C,Tablas!T32) -> 708995 | V32: 20201249 | W32: =U32/V32*1000 -> 35.096592 | X32: =AVERAGEIFS(Datos!$F:$F,Datos!$A:$A,Tablas!$C$18,Datos!$B:$B,Tablas!$C$3,Datos!$C:$C,Tablas!T32) -> 189559 | Y32: =IF($Y$2=$X$2,-X32,-W32) -> -35.096592 | AA32: #VALUE! | AB32: {=_FV(AA32,"Población")} -> 11046024
T33: North Carolina | U33: =SUMIFS(Datos!E:E,Datos!A:A,Tablas!C$18,Datos!B:B,Tablas!C$3,Datos!C:C,Tablas!T33) -> 226679 | V33: 11046024 | W33: =U33/V33*1000 -> 20.521321 | X33: =AVERAGEIFS(Datos!$F:$F,Datos!$A:$A,Tablas!$C$18,Datos!$B:$B,Tablas!$C$3,Datos!$C:$C,Tablas!T33) -> 82975 | Y33: =IF($Y$2=$X$2,-X33,-W33) -> -20.521321 | AA33: #VALUE! | AB33: {=_FV(AA33,"Población")} -> 796568
T34: North Dakota | U34: =SUMIFS(Datos!E:E,Datos!A:A,Tablas!C$18,Datos!B:B,Tablas!C$3,Datos!C:C,Tablas!T34) -> 23135 | V34: 796568 | W34: =U34/V34*1000 -> 29.043346 | X34: =AVERAGEIFS(Datos!$F:$F,Datos!$A:$A,Tablas!$C$18,Datos!$B:$B,Tablas!$C$3,Datos!$C:$C,Tablas!T34) -> 60044 | Y34: =IF($Y$2=$X$2,-X34,-W34) -> -29.043346 | AA34: #VALUE! | AB34: {=_FV(AA34,"Población")} -> 11883304
T35: Ohio | U35: =SUMIFS(Datos!E:E,Datos!A:A,Tablas!C$18,Datos!B:B,Tablas!C$3,Datos!C:C,Tablas!T35) -> 288615 | V35: 11883304 | W35: =U35/V35*1000 -> 24.287437 | X35: =AVERAGEIFS(Datos!$F:$F,Datos!$A:$A,Tablas!$C$18,Datos!$B:$B,Tablas!$C$3,Datos!$C:$C,Tablas!T35) -> 69967 | Y35: =IF($Y$2=$X$2,-X35,-W35) -> -24.287437 | AA35: #VALUE! | AB35: {=_FV(AA35,"Población")} -> 4095393
T36: Oklahoma | U36: =SUMIFS(Datos!E:E,Datos!A:A,Tablas!C$18,Datos!B:B,Tablas!C$3,Datos!C:C,Tablas!T36) -> 76757 | V36: 4095393 | W36: =U36/V36*1000 -> 18.742279 | X36: =AVERAGEIFS(Datos!$F:$F,Datos!$A:$A,Tablas!$C$18,Datos!$B:$B,Tablas!$C$3,Datos!$C:$C,Tablas!T36) -> 56323 | Y36: =IF($Y$2=$X$2,-X36,-W36) -> -18.742279 | AA36: #VALUE! | AB36: {=_FV(AA36,"Población")} -> 4272371
T37: Oregon | U37: =SUMIFS(Datos!E:E,Datos!A:A,Tablas!C$18,Datos!B:B,Tablas!C$3,Datos!C:C,Tablas!T37) -> 83715 | V37: 4272371 | W37: =U37/V37*1000 -> 19.594506 | X37: =AVERAGEIFS(Datos!$F:$F,Datos!$A:$A,Tablas!$C$18,Datos!$B:$B,Tablas!$C$3,Datos!$C:$C,Tablas!T37) -> 67638 | Y37: =IF($Y$2=$X$2,-X37,-W37) -> -19.594506 | AA37: #VALUE! | AB37: {=_FV(AA37,"Población")} -> 13078751
T38: Pennsylvania | U38: =SUMIFS(Datos!E:E,Datos!A:A,Tablas!C$18,Datos!B:B,Tablas!C$3,Datos!C:C,Tablas!T38) -> 321121 | V38: 13078751 | W38: =U38/V38*1000 -> 24.55288 | X38: =AVERAGEIFS(Datos!$F:$F,Datos!$A:$A,Tablas!$C$18,Datos!$B:$B,Tablas!$C$3,Datos!$C:$C,Tablas!T38) -> 85405 | Y38: =IF($Y$2=$X$2,-X38,-W38) -> -24.55288 | AA38: #VALUE! | AB38: {=_FV(AA38,"Población")} -> 1112308
T39: Rhode Island | U39: =SUMIFS(Datos!E:E,Datos!A:A,Tablas!C$18,Datos!B:B,Tablas!C$3,Datos!C:C,Tablas!T39) -> 32758 | V39: 1112308 | W39: =U39/V39*1000 -> 29.450476 | X39: =AVERAGEIFS(Datos!$F:$F,Datos!$A:$A,Tablas!$C$18,Datos!$B:$B,Tablas!$C$3,Datos!$C:$C,Tablas!T39) -> 89570 | Y39: =IF($Y$2=$X$2,-X39,-W39) -> -29.450476 | AA39: #VALUE! | AB39: {=_FV(AA39,"Población")} -> 5478831
T40: South Carolina | U40: =SUMIFS(Datos!E:E,Datos!A:A,Tablas!C$18,Datos!B:B,Tablas!C$3,Datos!C:C,Tablas!T40) -> 98790 | V40: 5478831 | W40: =U40/V40*1000 -> 18.031219 | X40: =AVERAGEIFS(Datos!$F:$F,Datos!$A:$A,Tablas!$C$18,Datos!$B:$B,Tablas!$C$3,Datos!$C:$C,Tablas!T40) -> 59859 | Y40: =IF($Y$2=$X$2,-X40,-W40) -> -18.031219 | AA40: #VALUE! | AB40: {=_FV(AA40,"Población")} -> 924669
...

Sheet Dashboard (format control)
A1: 2
A2: 6
A4: 1
B7: {=_xlfn.XLOOKUP(A2,Tablas!A3:A12,_xlfn.ANCHORARRAY(Tablas!B3))} -> Finanzas | D7: =_xlfn.XLOOKUP(A4,Tablas!M3:M6,Tablas!N3:N6) -> 2021
